<mujoco model="m710ic70">
  <option iterations="50" timestep="0.001" solver="PGS" gravity="0 0 -9.81" />

  <compiler angle="radian" meshdir="meshes" eulerseq="zyx" autolimits="true" />

  <default>
    <joint limited="true" damping="0.01" armature="0.01" frictionloss="0.01" />
    <geom condim="4" contype="1" conaffinity="15" friction="0.9 0.2 0.2" solref="0.001 2" />
    <motor ctrllimited="true" />
    <equality solref="0.001 2" />
    <default class="visualgeom">
      <geom material="visualgeom" condim="1" contype="0" conaffinity="0" />
    </default>
  </default>

  <worldbody>
    <light directional="true" diffuse="0.4 0.4 0.4" specular="0.1 0.1 0.1" pos="0 0 5.0" dir="0 0 -1" castshadow="false" />
    <light directional="true" diffuse="0.6 0.6 0.6" specular="0.2 0.2 0.2" pos="0 0 4" dir="0 0 -1" />
    <geom name="ground" type="plane" pos="0 0 0" size="100 100 0.001" quat="1 0 0 0" material="matplane" condim="3" conaffinity="15" />
    <camera name="fixed" pos="0 -3.0 0.5005" xyaxes="1 0 0 0 0 1" />
    <camera name="track" mode="trackcom" pos="0 -3.0 0.5005" xyaxes="1 0 0 0 0 1" />
    <body name="root" pos="0 0 0.0005" quat="1 0 0 0">
      <freejoint name="root" />
      <site name="imu" size="0.01" pos="0 0 0" />
      <geom size="0.0005 0.0005 0.0005" type="box" contype="1" conaffinity="0" density="0" group="1" class="visualgeom" />
      <geom type="box" rgba="" size="0.0005 0.0005 0.0005" />
      <body name="link_1" pos="0 0 0.565">
        <joint name="joint_1" pos="0 0 0" axis="0 0 1" range="-3.1415 3.1415" />
        <geom size="0.0005 0.0005 0.0005" type="box" contype="1" conaffinity="0" density="0" group="1" class="visualgeom" />
        <geom type="box" rgba="" size="0.0005 0.0005 0.0005" />
        <body name="link_2" pos="0.15 0 0">
          <joint name="joint_2" pos="0 0 0" axis="0 1 0" range="-1.5707 2.3561" />
          <geom size="0.0005 0.0005 0.0005" type="box" contype="1" conaffinity="0" density="0" group="1" class="visualgeom" />
          <geom type="box" rgba="" size="0.0005 0.0005 0.0005" />
          <body name="link_3" pos="0 0 0.87">
            <joint name="joint_3" pos="0 0 0" axis="0 -1 0" range="-2.7925 4.8869" />
            <geom size="0.0005 0.0005 0.0005" type="box" contype="1" conaffinity="0" density="0" group="1" class="visualgeom" />
            <geom type="box" rgba="" size="0.0005 0.0005 0.0005" />
            <body name="link_4" pos="0 0 0.17">
              <joint name="joint_4" pos="0 0 0" axis="-1 0 0" range="-6.283 6.283" />
              <geom size="0.0005 0.0005 0.0005" type="box" contype="1" conaffinity="0" density="0" group="1" class="visualgeom" />
              <geom type="box" rgba="" size="0.0005 0.0005 0.0005" />
              <body name="link_5" pos="1.016 0 0">
                <joint name="joint_5" pos="0 0 0" axis="0 -1 0" range="-2.1816 2.1816" />
                <geom size="0.0005 0.0005 0.0005" type="box" contype="1" conaffinity="0" density="0" group="1" class="visualgeom" />
                <geom type="box" rgba="" size="0.0005 0.0005 0.0005" />
                <body name="link_6" pos="0.175 0 0">
                  <joint name="joint_6" pos="0 0 0" axis="-1 0 0" range="-6.2831 6.2831" />
                  <geom size="0.0005 0.0005 0.0005" type="box" contype="1" conaffinity="0" density="0" group="1" class="visualgeom" />
                  <geom type="box" rgba="" size="0.0005 0.0005 0.0005" />
                </body>
              </body>
            </body>
          </body>
        </body>
      </body>
    </body>
  </worldbody>

  <asset>
    <texture name="texplane" type="2d" builtin="checker" rgb1=".0 .0 .0" rgb2=".8 .8 .8" width="100" height="100" />
    <material name="matplane" reflectance="0." texture="texplane" texrepeat="1 1" texuniform="true" />
    <material name="visualgeom" rgba="0.5 0.9 0.2 1" />
  </asset>

  <actuator>
    <motor name="joint_1" joint="joint_1" ctrllimited="true" ctrlrange="-1 1" gear="1" />
    <motor name="joint_2" joint="joint_2" ctrllimited="true" ctrlrange="-1 1" gear="1" />
    <motor name="joint_3" joint="joint_3" ctrllimited="true" ctrlrange="-1 1" gear="1" />
    <motor name="joint_4" joint="joint_4" ctrllimited="true" ctrlrange="-1 1" gear="1" />
    <motor name="joint_5" joint="joint_5" ctrllimited="true" ctrlrange="-1 1" gear="1" />
    <motor name="joint_6" joint="joint_6" ctrllimited="true" ctrlrange="-1 1" gear="1" />
  </actuator>

  <sensor>
    <actuatorpos name="joint_1_p" actuator="joint_1" />
    <actuatorvel name="joint_1_v" actuator="joint_1" />
    <actuatorfrc name="joint_1_f" actuator="joint_1" noise="0.001" />
    <actuatorpos name="joint_2_p" actuator="joint_2" />
    <actuatorvel name="joint_2_v" actuator="joint_2" />
    <actuatorfrc name="joint_2_f" actuator="joint_2" noise="0.001" />
    <actuatorpos name="joint_3_p" actuator="joint_3" />
    <actuatorvel name="joint_3_v" actuator="joint_3" />
    <actuatorfrc name="joint_3_f" actuator="joint_3" noise="0.001" />
    <actuatorpos name="joint_4_p" actuator="joint_4" />
    <actuatorvel name="joint_4_v" actuator="joint_4" />
    <actuatorfrc name="joint_4_f" actuator="joint_4" noise="0.001" />
    <actuatorpos name="joint_5_p" actuator="joint_5" />
    <actuatorvel name="joint_5_v" actuator="joint_5" />
    <actuatorfrc name="joint_5_f" actuator="joint_5" noise="0.001" />
    <actuatorpos name="joint_6_p" actuator="joint_6" />
    <actuatorvel name="joint_6_v" actuator="joint_6" />
    <actuatorfrc name="joint_6_f" actuator="joint_6" noise="0.001" />
    <framequat name="orientation" objtype="site" noise="0.001" objname="imu" />
    <gyro name="angular-velocity" site="imu" noise="0.005" cutoff="34.9" />
  </sensor>
</mujoco>